<?xml version="1.0" encoding="utf-8"?>
<!-- =================================================================================== -->
<!-- |    This document was autogenerated by xacro from fred.xacro                     | -->
<!-- |    EDITING THIS FILE BY HAND IS NOT RECOMMENDED                                 | -->
<!-- =================================================================================== -->
<robot name="kuka_lwr" xmlns:xacro="http://www.ros.org/wiki/xacro">
  <!-- right is either 1 (for right arm) or -1 (for left arm) -->
  <material name="black">
    <color rgba="0 0 0 1"/>
  </material>
  <material name="white">
    <color rgba="1 1 1 1"/>
  </material>
  <material name="red">
    <color rgba="0.8 0 0 1"/>
  </material>
  <material name="yellow">
    <color rgba="1 1 0 1"/>
  </material>
  <link name="base_link">
    <inertial>
      <origin rpy="0 0 0" xyz="0 0 0"/>
      <mass value=".0"/>
      <inertia ixx="0" ixy="0" ixz="0" iyy="0" iyz="0" izz="0"/>
    </inertial>
    <visual>
      <origin rpy="0 0 0" xyz="-0.08 -0.08 0"/>
      <geometry>
        <mesh filename="meshes_fred/base.stl" scale="0.001 0.001 0.001"/>
      </geometry>
      <material name="black"/>
    </visual>
  </link>
  <link name="base_plate">
    <inertial>
      <mass value="0.05"/>
      <origin rpy="0 0 0" xyz="0 0.09 0.0"/>
      <inertia ixx="4.50666666667e-05" ixy="0" ixz="0" iyy="9e-05" iyz="0" izz="4.50666666667e-05"/>
    </inertial>
    <visual>
      <origin rpy="0 0 0" xyz="-0.06 -0.06 0"/>
      <geometry>
        <mesh filename="meshes_fred/base_plate.stl" scale="0.001 0.001 0.001"/>
      </geometry>
      <material name="black"/>
    </visual>
  </link>
  <joint name="base_to_base_plate" type="revolute">
    <limit effort="1000.0" lower="0.0" upper="3.14159265359" velocity="10"/>
    <parent link="base_link"/>
    <child link="base_plate"/>
    <origin rpy="0 0 -1.57079632679" xyz="0 0 0.0545"/>
    <axis xyz="0 0 1"/>
  </joint>
  <link name="arm_lower">
    <inertial>
      <mass value="0.2"/>
      <origin rpy="0 0 0" xyz="0 0.09 0.0"/>
      <inertia ixx="0.0006" ixy="0" ixz="0" iyy="0.00012" iyz="0" izz="0.0006"/>
    </inertial>
    <visual>
      <origin rpy="0 1.57079632679 0" xyz="-0.032 -0.0243 0.030"/>
      <geometry>
        <mesh filename="meshes_fred/arm_lower.stl" scale="0.001 0.001 0.001"/>
      </geometry>
      <material name="red"/>
    </visual>
    <collision>
      <origin rpy="0 1.57079632679 0" xyz="-0.032 -0.0243 0.030"/>
      <geometry>
        <mesh filename="meshes_fred/arm_lower_col.stl" scale="0.001 0.001 0.001"/>
      </geometry>
    </collision>
  </link>
  <joint name="base_plate_to_arm_lower" type="revolute">
    <limit effort="1000.0" lower="0.0" upper="3.14159265359" velocity="10"/>
    <parent link="base_plate"/>
    <child link="arm_lower"/>
    <origin rpy="3.14159265359 0 3.14159265359" xyz="0 0 0.036"/>
    <axis xyz="-1 0 0"/>
  </joint>
  <link name="arm_upper">
    <inertial>
      <mass value="0.3"/>
      <origin rpy="0 0 0" xyz="0.0 0.03 -0.01"/>
      <inertia ixx="0.00045" ixy="0" ixz="0" iyy="0.00013" iyz="0" izz="0.0004"/>
    </inertial>
    <visual>
      <origin rpy="0 3.14159265359 0" xyz="0.019 -0.0415 0.02"/>
      <geometry>
        <mesh filename="meshes_fred/arm_upper.stl" scale="0.001 0.001 0.001"/>
      </geometry>
      195
      
      <material name="red"/>
    </visual>
    <collision>
      <origin rpy="0 3.14159265359 0" xyz="0.019 -0.0415 0.02"/>
      <geometry>
        <mesh filename="meshes_fred/arm_upper.stl" scale="0.001 0.001 0.001"/>
      </geometry>
      195
   
    </collision>
  </link>
  <joint name="arm_lower_to_arm_upper" type="revolute">
    <limit effort="1000.0" lower="-1.57079632679" upper="3.14159265359" velocity="10"/>
    <parent link="arm_lower"/>
    <child link="arm_upper"/>
    <origin rpy="1.57079632679 0 0" xyz="0 0.158 0"/>
    <axis xyz="-1 0 0"/>
  </joint>
  <link name="wrist">
    <inertial>
      <mass value="0.1"/>
      <origin rpy="0 0 0" xyz="0.0 0.065 0.0"/>
      <inertia ixx="0.000133333333333" ixy="0" ixz="0" iyy="5.41666666667e-05" iyz="0" izz="0.000160833333333"/>
    </inertial>
    <visual>
      <origin rpy="0 0 0" xyz="-0.036625 0 -0.02"/>
      <geometry>
        <mesh filename="meshes_fred/wrist.stl" scale="0.001 0.001 0.001"/>
      </geometry>
      <material name="red"/>
    </visual>
    <collision>
      <origin rpy="0 0 0" xyz="-0.036625 0 -0.02"/>
      <geometry>
        <mesh filename="meshes_fred/wrist.stl" scale="0.001 0.001 0.001"/>
      </geometry>
    </collision>
  </link>
  <joint name="arm_upper_to_wrist" type="continuous">
    <parent link="arm_upper"/>
    <child link="wrist"/>
    <origin xyz="0 0.102 0"/>
    <axis xyz="0 1 0"/>
  </joint>
  <link name="wrist_servo">
    <inertial>
      <mass value="0.04"/>
      <origin rpy="0 0 0" xyz="0.0 0.0 -0.015"/>
      <inertia ixx="0.00030675" ixy="0" ixz="0" iyy="9.75e-06" iyz="0" izz="0.000303"/>
    </inertial>
    <visual>
      <origin rpy="0 0 1.57079632679" xyz="0.0145 -0.017 -0.03525"/>
      <geometry>
        <mesh filename="meshes_fred/servo.stl" scale="0.001 0.001 0.001"/>
      </geometry>
      <material name="red"/>
    </visual>
    <collision>
      <origin rpy="0 0 1.57079632679" xyz="0.0145 -0.017 -0.03525"/>
      <geometry>
        <mesh filename="meshes_fred/servo.stl" scale="0.001 0.001 0.001"/>
      </geometry>
    </collision>
  </link>
  <joint name="wrist_to_wrist_servo" type="continuous">
    <parent link="wrist"/>
    <child link="wrist_servo"/>
    <origin xyz="0 0.11625 0"/>
    <axis xyz="-1 0 0"/>
  </joint>
  <link name="gripper">
    <inertial>
      <mass value="0.01"/>
      <origin rpy="0 0 0" xyz="0.0 0.038 0.0"/>
      <inertia ixx="5.4375e-06" ixy="0" ixz="0" iyy="3.75e-06" iyz="0" izz="7.6875e-06"/>
    </inertial>
    <visual>
      <origin rpy="-1.57079632679 0 0" xyz="-0.03 0 0.015"/>
      <geometry>
        <mesh filename="meshes_fred/gripper.stl" scale="0.001 0.001 0.001"/>
      </geometry>
      <material name="black"/>
    </visual>
    <collision>
      <origin rpy="-1.57079632679 0 0" xyz="-0.03 0 0.015"/>
      <geometry>
        <mesh filename="meshes_fred/gripper.stl" scale="0.001 0.001 0.001"/>
      </geometry>
    </collision>
  </link>
  <joint name="wrist_servo_to_gripper" type="continuous">
    <parent link="wrist_servo"/>
    <child link="gripper"/>
    <origin xyz="0 0.017 0"/>
    <axis xyz="0 1 0"/>
  </joint>
  <link name="sphere1">
    <inertial>
      <origin rpy="0 0 0" xyz="0 0 0"/>
      <mass value=".0"/>
      <inertia ixx="0" ixy="0" ixz="0" iyy="0" iyz="0" izz="0"/>
    </inertial>
    <visual>
      <origin rpy="0 0 0" xyz="0 0 0"/>
      <geometry>
        <sphere radius="0.01"/>
      </geometry>
      <material name="yellow"/>
    </visual>
    <collision>
      <origin rpy="0 0 0" xyz="0 0 0"/>
      <geometry>
        <sphere radius="0.01"/>
      </geometry>
    </collision>
  </link>
  <joint name="wrist_to_sphere1" type="continuous">
    <parent link="wrist"/>
    <child link="sphere1"/>
    <origin xyz="0 0.05 0"/>
    <axis xyz="0 1 0"/>
  </joint>
  <link name="sphere2">
    <inertial>
      <origin rpy="0 0 0" xyz="0 0 0"/>
      <mass value=".0"/>
      <inertia ixx="0" ixy="0" ixz="0" iyy="0" iyz="0" izz="0"/>
    </inertial>
    <visual>
      <origin rpy="0 0 0" xyz="0 0 0"/>
      <geometry>
        <sphere radius="0.01"/>
      </geometry>
      <material name="yellow"/>
    </visual>
    <collision>
      <origin rpy="0 0 0" xyz="0 0 0"/>
      <geometry>
        <sphere radius="0.01"/>
      </geometry>
    </collision>
  </link>
  <joint name="wrist_servo_to_sphere2" type="continuous">
    <parent link="wrist_servo"/>
    <child link="sphere2"/>
    <origin xyz="0 0 0"/>
    <axis xyz="0 1 0"/>
  </joint>
  <link name="sphere3">
    <inertial>
      <origin rpy="0 0 0" xyz="0 0 0"/>
      <mass value=".0"/>
      <inertia ixx="0" ixy="0" ixz="0" iyy="0" iyz="0" izz="0"/>
    </inertial>
    <visual>
      <origin rpy="0 0 0" xyz="0 0 0"/>
      <geometry>
        <sphere radius="0.01"/>
      </geometry>
      <material name="yellow"/>
    </visual>
    <collision>
      <origin rpy="0 0 0" xyz="0 0 0"/>
      <geometry>
        <sphere radius="0.01"/>
      </geometry>
    </collision>
  </link>
  <joint name="wrist_sphere3" type="continuous">
    <parent link="gripper"/>
    <child link="sphere3"/>
    <origin xyz="0 0.1 0"/>
    <axis xyz="0 1 0"/>
  </joint>
</robot>

