<?xml version="1.0"?>
<robot xmlns:xacro="http://www.ros.org/wiki/xacro" name="kuka_lwr">

 <!-- <xacro:property name="dir" value="file:///home/thomas/tutorial_ws/urdf_tutorial/urdf/" /> -->
<xacro:property name="dir" value="" />
 <xacro:property name="M_PI" value="3.1415926535897931" />
 <xacro:property name="name" value="kuka" />
  <!--
     Little helper macro to define the inertia matrix needed
     for links.
     -->
  <!-- width is along x axis
       length is along y axis
       height is along z axis
  -->
  <xacro:macro name="cuboid_inertia_def" params="width height length mass">
    <inertia ixx="${mass * (height * height + length * length) / 12}"
             iyy="${mass * (width * width + height * height) / 12}"
             izz="${mass * (width * width + length * length) / 12}"
             ixy="0" iyz="0" ixz="0"/>
  </xacro:macro>

  <!-- length is along the y-axis! -->
  <xacro:macro name="cylinder_inertia_def" params="radius length mass">
    <inertia ixx="${mass * (3 * radius * radius + length * length) / 12}"
             iyy="${mass * radius* radius / 2}"
             izz="${mass * (3 * radius * radius + length * length) / 12}"
             ixy="0" iyz="0" ixz="0"/>
  </xacro:macro>

  <xacro:property name="base_plate_mass" value="0.05"/>
  <xacro:property name="arm_lower_mass" value="0.2"/>
  <xacro:property name="arm_upper_mass" value="0.3"/>
  <xacro:property name="wrist_mass" value="0.1"/>
  <xacro:property name="wrist_servo_mass" value="0.04"/>
  <xacro:property name="gripper_mass" value="0.01"/>


  <xacro:property name="arm_velocity_scale_factor" value="1"/>
  <xacro:property name="right" value="0" />
  <!-- right is either 1 (for right arm) or -1 (for left arm) -->


  <material name="black">
    <color rgba="0 0 0 1"/>
  </material>
  <material name="white">
    <color rgba="1 1 1 1"/>
  </material>
  <material name="red">
    <color rgba="0.8 0 0 1"/>
  </material>


  <link name="base_link">
    <inertial>
      <origin rpy="0 0 0" xyz="0 0 0"/>
       <mass value=".0"/>
       <inertia ixx="0" ixy="0" ixz="0" iyy="0" iyz="0" izz="0"/>
    </inertial>
    <visual>
      <origin rpy="0 0 0" xyz="-0.08 -0.08 0"/>
      <geometry>
        <mesh filename="${dir}meshes_fred/base.stl" scale="0.001 0.001 0.001"/>
      </geometry>
      <material name="black"/>
    </visual>
  </link>

  <link name="base_plate">
    <inertial>
      <mass value="${base_plate_mass}"/>
      <origin rpy="0 0 0" xyz="0 0.09 0.0"/>
      <cylinder_inertia_def radius="0.06" length="0.004"
                          mass="${base_plate_mass}"/>
    </inertial>
    <visual>
      <origin rpy="0 0 0" xyz="-0.06 -0.06 0"/>
      <geometry>
        <mesh filename="${dir}meshes_fred/base_plate.stl" scale="0.001 0.001 0.001"/>
      </geometry>
      <material name="black"/>
    </visual>
  </link>
  <joint name="base_to_base_plate" type="revolute">
    <limit effort="1000.0" lower="0.0" upper="${M_PI}" velocity="10"/>
    <parent link="base_link"/>
    <child link="base_plate"/>
    <origin rpy="0 0 -${M_PI/2}" xyz="0 0 0.0545"/>
    <axis xyz="0 0 1"/>
  </joint>

  <link name="arm_lower">
    <inertial>
      <mass value="${arm_lower_mass}"/>
      <origin rpy="0 0 0" xyz="0 0.09 0.0"/>
      <cuboid_inertia_def width="0.06" length="0.18" height="0.06"
                          mass="${arm_lower_mass}"/>
    </inertial>
    <visual>
      <origin rpy="0 ${M_PI/2} 0" xyz="-0.032 -0.0243 0.030"/>
      <geometry>
        <mesh filename="${dir}meshes_fred/arm_lower.stl" scale="0.001 0.001 0.001"/>
      </geometry>
      <material name="red"/>
    </visual>

    <collision>
      <origin rpy="0 ${M_PI/2} 0" xyz="-0.032 -0.0243 0.030"/>
      <geometry>
        <mesh filename="${dir}meshes_fred/arm_lower_col.stl" scale="0.001 0.001 0.001"/>
      </geometry>
    </collision>
  </link>
  <joint name="base_plate_to_arm_lower" type="revolute">
    <limit effort="1000.0" lower="0.0" upper="${M_PI}" velocity="10"/>
    <parent link="base_plate"/>
    <child link="arm_lower"/>
    <origin rpy="${M_PI} 0 ${M_PI}" xyz="0 0 0.036"/>
    <axis xyz="-1 0 0"/>
  </joint>


  <link name="arm_upper">
    <inertial>
      <mass value="${arm_upper_mass}"/>
      <origin rpy="0 0 0" xyz="0.0 0.03 -0.01"/>
      <cuboid_inertia_def width="0.04" length="0.12" height="0.06"
                          mass="${arm_upper_mass}"/>
    </inertial>
    <visual>
      <origin rpy="0 ${M_PI} 0" xyz="0.019 -0.0415 0.02"/>
      <geometry>
        <mesh filename="${dir}meshes_fred/arm_upper.stl" scale="0.001 0.001 0.001"/>
      </geometry>195
      <material name="red"/>
    </visual>
    <collision>
      <origin rpy="0 ${M_PI} 0" xyz="0.019 -0.0415 0.02"/>
      <geometry>
        <mesh filename="${dir}meshes_fred/arm_upper.stl" scale="0.001 0.001 0.001"/>
      </geometry>195
   </collision>
  </link>
  <joint name="arm_lower_to_arm_upper" type="revolute">
    <limit effort="1000.0" lower="${-M_PI/2}" upper="${M_PI}" velocity="10"/>
    <parent link="arm_lower"/>
    <child link="arm_upper"/>
    <origin rpy="${M_PI/2} 0 0" xyz="0 0.158 0"/>
    <axis xyz="-1 0 0"/>
  </joint>

  <link name="wrist">
    <inertial>
      <mass value="${wrist_mass}"/>
      <origin rpy="0 0 0" xyz="0.0 0.065 0.0"/>
      <cuboid_inertia_def width="0.07" length="0.12" height="0.04"
                          mass="${wrist_mass}"/>
    </inertial>
    <visual>
      <origin rpy="0 0 0" xyz="-0.036625 0 -0.02"/>
      <geometry>
        <mesh filename="${dir}meshes_fred/wrist.stl" scale="0.001 0.001 0.001"/>
      </geometry>
      <material name="red"/>
    </visual>
    <collision>
      <origin rpy="0 0 0" xyz="-0.036625 0 -0.02"/>
      <geometry>
        <mesh filename="${dir}meshes_fred/wrist.stl" scale="0.001 0.001 0.001"/>
      </geometry>
    </collision>
  </link>
  <joint name="arm_upper_to_wrist" type="continuous">
    <parent link="arm_upper"/>
    <child link="wrist"/>
    <origin xyz="0 0.102 0"/>
    <axis xyz="0 1 0"/>
  </joint>


  <link name="wrist_servo">
    <inertial>
      <mass value="${wrist_servo_mass}"/>
      <origin rpy="0 0 0" xyz="0.0 0.0 -0.015"/>
      <cuboid_inertia_def width="0.03" length="0.3" height="0.045"
                          mass="${wrist_servo_mass}"/>
    </inertial>
    <visual>
      <origin rpy="0 0 ${M_PI/2}" xyz="0.0145 -0.017 -0.03525"/>
      <geometry>
        <mesh filename="${dir}meshes_fred/servo.stl" scale="0.001 0.001 0.001"/>
      </geometry>
      <material name="red"/>
    </visual>
    <collision>
      <origin rpy="0 0 ${M_PI/2}" xyz="0.0145 -0.017 -0.03525"/>
      <geometry>
        <mesh filename="${dir}meshes_fred/servo.stl" scale="0.001 0.001 0.001"/>
      </geometry>
    </collision>
  </link>
  <joint name="wrist_to_wrist_servo" type="continuous">
    <parent link="wrist"/>
    <child link="wrist_servo"/>
    <origin xyz="0 0.11625 0"/>
    <axis xyz="-1 0 0"/>
  </joint>


  <link name="gripper">
    <inertial>
      <mass value="${gripper_mass}"/>
      <origin rpy="0 0 0" xyz="0.0 0.038 0.0"/>
      <cuboid_inertia_def width="0.06" length="0.075" height="0.03"
                          mass="${gripper_mass}"/>
    </inertial>
    <visual>
      <origin rpy="${-M_PI/2} 0 0" xyz="-0.03 0 0.015"/>
      <geometry>
        <mesh filename="${dir}meshes_fred/gripper.stl" scale="0.001 0.001 0.001"/>
      </geometry>
      <material name="black"/>
    </visual>
    <collision>
      <origin rpy="${-M_PI/2} 0 0" xyz="-0.03 0 0.015"/>
      <geometry>
        <mesh filename="${dir}meshes_fred/gripper.stl" scale="0.001 0.001 0.001"/>
      </geometry>
    </collision>
  </link>
  <joint name="wrist_servo_to_gripper" type="continuous">
    <parent link="wrist_servo"/>
    <child link="gripper"/>
    <origin xyz="0 0.017 0"/>
    <axis xyz="0 1 0"/>
  </joint>

</robot>
